2025-05-29 10:30:23,814 - x3270_emulator - INFO - Inicializando X3270 (visible=True, model=2)
2025-05-29 10:30:23,817 - x3270_emulator - INFO - Criando aplicativo emulador
2025-05-29 10:30:23,818 - x3270_emulator - INFO - Criando Wc3270App (Windows, visível)
2025-05-29 10:30:23,818 - x3270_emulator - INFO - Inicializando Wc3270App com modelo: 2
2025-05-29 10:30:23,820 - x3270_emulator - INFO - Inicializando ExecutableApp (shell=True, model=2)
2025-05-29 10:30:24,000 - x3270_emulator - INFO - Processo iniciado com PID: 26424
2025-05-29 10:30:24,000 - x3270_emulator - INFO - Conectando ao host: localhost:992 (tls=False)
2025-05-29 10:30:24,001 - x3270_emulator - INFO - Conectando ao host: localhost:992
2025-05-29 10:30:24,161 - x3270_emulator - INFO - Processo iniciado com PID: 25096
2025-05-29 10:30:24,161 - x3270_emulator - INFO - Criando socket para porta 65468
2025-05-29 10:30:26,194 - x3270_emulator - INFO - Conexão de socket estabelecida com sucesso
2025-05-29 10:30:26,194 - x3270_emulator - INFO - Conexão estabelecida com sucesso
2025-05-29 10:30:26,195 - x3270_emulator - INFO - Executando comando wait com args=(5, '3270mode'), kwargs={}
2025-05-29 10:30:26,196 - x3270_emulator - INFO - Executando comando: b'wait(5, 3270mode)'
2025-05-29 10:30:31,207 - x3270_emulator - ERROR - Comando falhou: Wait(): Timed out
2025-05-29 10:30:31,207 - x3270_emulator - ERROR - Erro durante execução do comando: Wait(): Timed out
Traceback (most recent call last):
  File "C:\projetos\pyx3270\pyx3270\emulator.py", line 191, in execute
    return self.handle_result(result.decode('utf-8'))
           ~~~~~~~~~~~~~~~~~~^^^^^^^^^^^^^^^^^^^^^^^^
  File "C:\projetos\pyx3270\pyx3270\emulator.py", line 230, in handle_result
    raise CommandError(error_msg)
exceptions.CommandError: Wait(): Timed out
2025-05-29 10:30:31,211 - x3270_emulator - ERROR - Erro ao executar comando: Wait(): Timed out
Traceback (most recent call last):
  File "C:\projetos\pyx3270\pyx3270\emulator.py", line 792, in _exec_command
    cmd.execute()
    ~~~~~~~~~~~^^
  File "C:\projetos\pyx3270\pyx3270\emulator.py", line 191, in execute
    return self.handle_result(result.decode('utf-8'))
           ~~~~~~~~~~~~~~~~~~^^^^^^^^^^^^^^^^^^^^^^^^
  File "C:\projetos\pyx3270\pyx3270\emulator.py", line 230, in handle_result
    raise CommandError(error_msg)
exceptions.CommandError: Wait(): Timed out
2025-05-29 10:30:31,212 - x3270_emulator - ERROR - Erro ao executar comando wait: Wait(): Timed out
Traceback (most recent call last):
  File "C:\projetos\pyx3270\pyx3270\emulator.py", line 722, in command_func
    cmd = self._exec_command(
        f'{name}({all_args})'.encode('utf8')
    )
  File "C:\projetos\pyx3270\pyx3270\emulator.py", line 792, in _exec_command
    cmd.execute()
    ~~~~~~~~~~~^^
  File "C:\projetos\pyx3270\pyx3270\emulator.py", line 191, in execute
    return self.handle_result(result.decode('utf-8'))
           ~~~~~~~~~~~~~~~~~~^^^^^^^^^^^^^^^^^^^^^^^^
  File "C:\projetos\pyx3270\pyx3270\emulator.py", line 230, in handle_result
    raise CommandError(error_msg)
exceptions.CommandError: Wait(): Timed out
2025-05-29 10:30:31,213 - x3270_emulator - WARNING - CommandError durante conexão: Wait(): Timed out
2025-05-29 10:30:31,686 - x3270_emulator - ERROR - Comando __iter__ não encontrado.
2025-05-29 10:31:11,053 - x3270_emulator - INFO - Inicializando X3270 (visible=True, model=2)
2025-05-29 10:31:11,053 - x3270_emulator - INFO - Criando aplicativo emulador
2025-05-29 10:31:11,054 - x3270_emulator - INFO - Criando Wc3270App (Windows, visível)
2025-05-29 10:31:11,054 - x3270_emulator - INFO - Inicializando Wc3270App com modelo: 2
2025-05-29 10:31:11,054 - x3270_emulator - INFO - Inicializando ExecutableApp (shell=True, model=2)
2025-05-29 10:31:11,203 - x3270_emulator - INFO - Processo iniciado com PID: 26708
2025-05-29 10:31:11,203 - x3270_emulator - INFO - Conectando ao host: localhost:992 (tls=False)
2025-05-29 10:31:11,203 - x3270_emulator - INFO - Conectando ao host: localhost:992
2025-05-29 10:31:11,316 - x3270_emulator - INFO - Processo iniciado com PID: 2844
2025-05-29 10:31:11,317 - x3270_emulator - INFO - Criando socket para porta 65504
2025-05-29 10:31:13,357 - x3270_emulator - WARNING - Conexão recusada, tentando novamente em 1s (tentativa 1/5)
2025-05-29 10:31:14,361 - x3270_emulator - INFO - Conexão de socket estabelecida com sucesso
2025-05-29 10:31:14,361 - x3270_emulator - INFO - Conexão estabelecida com sucesso
2025-05-29 10:31:14,362 - x3270_emulator - INFO - Executando comando wait com args=(5, '3270mode'), kwargs={}
2025-05-29 10:31:14,362 - x3270_emulator - INFO - Executando comando: b'wait(5, 3270mode)'
2025-05-29 10:31:17,712 - x3270_emulator - ERROR - Erro ao ler do socket: [WinError 10054] An existing connection was forcibly closed by the remote host
Traceback (most recent call last):
  File "C:\projetos\pyx3270\pyx3270\emulator.py", line 374, in readline
    line = self.socket_fh.readline()
  File "C:\Users\e5674469\.pyenv\pyenv-win\versions\3.13.1\Lib\socket.py", line 719, in readinto
    return self._sock.recv_into(b)
           ~~~~~~~~~~~~~~~~~~~~^^^
ConnectionResetError: [WinError 10054] An existing connection was forcibly closed by the remote host
2025-05-29 10:31:17,715 - x3270_emulator - ERROR - Erro durante execução do comando: 
Traceback (most recent call last):
  File "C:\projetos\pyx3270\pyx3270\emulator.py", line 374, in readline
    line = self.socket_fh.readline()
  File "C:\Users\e5674469\.pyenv\pyenv-win\versions\3.13.1\Lib\socket.py", line 719, in readinto
    return self._sock.recv_into(b)
           ~~~~~~~~~~~~~~~~~~~~^^^
ConnectionResetError: [WinError 10054] An existing connection was forcibly closed by the remote host

During handling of the above exception, another exception occurred:

Traceback (most recent call last):
  File "C:\projetos\pyx3270\pyx3270\emulator.py", line 185, in execute
    line = self.app.readline()
  File "C:\projetos\pyx3270\pyx3270\emulator.py", line 379, in readline
    raise NotConnectedException
exceptions.NotConnectedException
2025-05-29 10:31:17,717 - x3270_emulator - ERROR - Erro ao executar comando: 
Traceback (most recent call last):
  File "C:\projetos\pyx3270\pyx3270\emulator.py", line 374, in readline
    line = self.socket_fh.readline()
  File "C:\Users\e5674469\.pyenv\pyenv-win\versions\3.13.1\Lib\socket.py", line 719, in readinto
    return self._sock.recv_into(b)
           ~~~~~~~~~~~~~~~~~~~~^^^
ConnectionResetError: [WinError 10054] An existing connection was forcibly closed by the remote host

During handling of the above exception, another exception occurred:

Traceback (most recent call last):
  File "C:\projetos\pyx3270\pyx3270\emulator.py", line 792, in _exec_command
    cmd.execute()
    ~~~~~~~~~~~^^
  File "C:\projetos\pyx3270\pyx3270\emulator.py", line 185, in execute
    line = self.app.readline()
  File "C:\projetos\pyx3270\pyx3270\emulator.py", line 379, in readline
    raise NotConnectedException
exceptions.NotConnectedException
2025-05-29 10:31:17,719 - x3270_emulator - ERROR - Erro ao executar comando wait: 
Traceback (most recent call last):
  File "C:\projetos\pyx3270\pyx3270\emulator.py", line 374, in readline
    line = self.socket_fh.readline()
  File "C:\Users\e5674469\.pyenv\pyenv-win\versions\3.13.1\Lib\socket.py", line 719, in readinto
    return self._sock.recv_into(b)
           ~~~~~~~~~~~~~~~~~~~~^^^
ConnectionResetError: [WinError 10054] An existing connection was forcibly closed by the remote host

During handling of the above exception, another exception occurred:

Traceback (most recent call last):
  File "C:\projetos\pyx3270\pyx3270\emulator.py", line 722, in command_func
    cmd = self._exec_command(
        f'{name}({all_args})'.encode('utf8')
    )
  File "C:\projetos\pyx3270\pyx3270\emulator.py", line 792, in _exec_command
    cmd.execute()
    ~~~~~~~~~~~^^
  File "C:\projetos\pyx3270\pyx3270\emulator.py", line 185, in execute
    line = self.app.readline()
  File "C:\projetos\pyx3270\pyx3270\emulator.py", line 379, in readline
    raise NotConnectedException
exceptions.NotConnectedException
2025-05-29 10:31:17,722 - x3270_emulator - ERROR - Erro ao conectar: 
Traceback (most recent call last):
  File "C:\projetos\pyx3270\pyx3270\emulator.py", line 374, in readline
    line = self.socket_fh.readline()
  File "C:\Users\e5674469\.pyenv\pyenv-win\versions\3.13.1\Lib\socket.py", line 719, in readinto
    return self._sock.recv_into(b)
           ~~~~~~~~~~~~~~~~~~~~^^^
ConnectionResetError: [WinError 10054] An existing connection was forcibly closed by the remote host

During handling of the above exception, another exception occurred:

Traceback (most recent call last):
  File "C:\projetos\pyx3270\pyx3270\emulator.py", line 851, in connect_host
    self.wait(5, '3270mode')
    ~~~~~~~~~^^^^^^^^^^^^^^^
  File "C:\projetos\pyx3270\pyx3270\emulator.py", line 722, in command_func
    cmd = self._exec_command(
        f'{name}({all_args})'.encode('utf8')
    )
  File "C:\projetos\pyx3270\pyx3270\emulator.py", line 792, in _exec_command
    cmd.execute()
    ~~~~~~~~~~~^^
  File "C:\projetos\pyx3270\pyx3270\emulator.py", line 185, in execute
    line = self.app.readline()
  File "C:\projetos\pyx3270\pyx3270\emulator.py", line 379, in readline
    raise NotConnectedException
exceptions.NotConnectedException
2025-05-29 10:32:01,341 - x3270_emulator - INFO - Inicializando X3270 (visible=True, model=2)
2025-05-29 10:32:01,342 - x3270_emulator - INFO - Criando aplicativo emulador
2025-05-29 10:32:01,342 - x3270_emulator - INFO - Criando Wc3270App (Windows, visível)
2025-05-29 10:32:01,342 - x3270_emulator - INFO - Inicializando Wc3270App com modelo: 2
2025-05-29 10:32:01,345 - x3270_emulator - INFO - Inicializando ExecutableApp (shell=True, model=2)
2025-05-29 10:32:01,482 - x3270_emulator - INFO - Processo iniciado com PID: 27296
2025-05-29 10:32:01,482 - x3270_emulator - INFO - Conectando ao host: localhost:992 (tls=False)
2025-05-29 10:32:01,482 - x3270_emulator - INFO - Conectando ao host: localhost:992
2025-05-29 10:32:01,750 - x3270_emulator - INFO - Processo iniciado com PID: 10476
2025-05-29 10:32:01,750 - x3270_emulator - INFO - Criando socket para porta 49170
2025-05-29 10:32:03,291 - x3270_emulator - INFO - Conexão de socket estabelecida com sucesso
2025-05-29 10:32:03,292 - x3270_emulator - INFO - Conexão estabelecida com sucesso
2025-05-29 10:32:03,292 - x3270_emulator - INFO - Executando comando wait com args=(5, '3270mode'), kwargs={}
2025-05-29 10:32:03,293 - x3270_emulator - INFO - Executando comando: b'wait(5, 3270mode)'
2025-05-29 10:32:08,300 - x3270_emulator - ERROR - Comando falhou: Wait(): Timed out
2025-05-29 10:32:08,300 - x3270_emulator - ERROR - Erro durante execução do comando: Wait(): Timed out
Traceback (most recent call last):
  File "C:\projetos\pyx3270\pyx3270\emulator.py", line 191, in execute
    return self.handle_result(result.decode('utf-8'))
           ~~~~~~~~~~~~~~~~~~^^^^^^^^^^^^^^^^^^^^^^^^
  File "C:\projetos\pyx3270\pyx3270\emulator.py", line 231, in handle_result
    raise CommandError(error_msg)
exceptions.CommandError: Wait(): Timed out
2025-05-29 10:32:08,304 - x3270_emulator - ERROR - Erro ao executar comando: Wait(): Timed out
Traceback (most recent call last):
  File "C:\projetos\pyx3270\pyx3270\emulator.py", line 795, in _exec_command
    cmd.execute()
    ~~~~~~~~~~~^^
  File "C:\projetos\pyx3270\pyx3270\emulator.py", line 191, in execute
    return self.handle_result(result.decode('utf-8'))
           ~~~~~~~~~~~~~~~~~~^^^^^^^^^^^^^^^^^^^^^^^^
  File "C:\projetos\pyx3270\pyx3270\emulator.py", line 231, in handle_result
    raise CommandError(error_msg)
exceptions.CommandError: Wait(): Timed out
2025-05-29 10:32:08,305 - x3270_emulator - ERROR - Erro ao executar comando wait: Wait(): Timed out
Traceback (most recent call last):
  File "C:\projetos\pyx3270\pyx3270\emulator.py", line 725, in command_func
    cmd = self._exec_command(
        f'{name}({all_args})'.encode('utf8')
    )
  File "C:\projetos\pyx3270\pyx3270\emulator.py", line 795, in _exec_command
    cmd.execute()
    ~~~~~~~~~~~^^
  File "C:\projetos\pyx3270\pyx3270\emulator.py", line 191, in execute
    return self.handle_result(result.decode('utf-8'))
           ~~~~~~~~~~~~~~~~~~^^^^^^^^^^^^^^^^^^^^^^^^
  File "C:\projetos\pyx3270\pyx3270\emulator.py", line 231, in handle_result
    raise CommandError(error_msg)
exceptions.CommandError: Wait(): Timed out
2025-05-29 10:32:08,306 - x3270_emulator - WARNING - CommandError durante conexão: Wait(): Timed out
2025-05-29 10:32:08,804 - x3270_emulator - ERROR - Comando __iter__ não encontrado.
2025-05-29 10:32:36,161 - x3270_emulator - INFO - Inicializando X3270 (visible=True, model=2)
2025-05-29 10:32:36,161 - x3270_emulator - INFO - Criando aplicativo emulador
2025-05-29 10:32:36,162 - x3270_emulator - INFO - Criando Wc3270App (Windows, visível)
2025-05-29 10:32:36,162 - x3270_emulator - INFO - Inicializando Wc3270App com modelo: 2
2025-05-29 10:32:36,163 - x3270_emulator - INFO - Inicializando ExecutableApp (shell=True, model=2)
2025-05-29 10:32:36,308 - x3270_emulator - INFO - Processo iniciado com PID: 13376
2025-05-29 10:32:36,308 - x3270_emulator - INFO - Conectando ao host: localhost:992 (tls=False)
2025-05-29 10:32:36,308 - x3270_emulator - INFO - Conectando ao host: localhost:992
2025-05-29 10:32:36,456 - x3270_emulator - INFO - Processo iniciado com PID: 28136
2025-05-29 10:32:36,456 - x3270_emulator - INFO - Criando socket para porta 49198
2025-05-29 10:32:37,997 - x3270_emulator - INFO - Conexão de socket estabelecida com sucesso
2025-05-29 10:32:37,997 - x3270_emulator - INFO - Conexão estabelecida com sucesso
2025-05-29 10:32:37,998 - x3270_emulator - INFO - Executando comando wait com args=(5, '3270mode'), kwargs={}
2025-05-29 10:32:37,998 - x3270_emulator - INFO - Executando comando: b'wait(5, 3270mode)'
2025-05-29 10:32:42,999 - x3270_emulator - ERROR - Comando falhou: Wait(): Timed out
2025-05-29 10:32:43,000 - x3270_emulator - ERROR - Erro durante execução do comando: Wait(): Timed out
Traceback (most recent call last):
  File "C:\projetos\pyx3270\pyx3270\emulator.py", line 191, in execute
    return self.handle_result(result.decode('utf-8'))
           ~~~~~~~~~~~~~~~~~~^^^^^^^^^^^^^^^^^^^^^^^^
  File "C:\projetos\pyx3270\pyx3270\emulator.py", line 231, in handle_result
    raise CommandError(error_msg)
exceptions.CommandError: Wait(): Timed out
2025-05-29 10:32:43,006 - x3270_emulator - ERROR - Erro ao executar comando: Wait(): Timed out
Traceback (most recent call last):
  File "C:\projetos\pyx3270\pyx3270\emulator.py", line 795, in _exec_command
    cmd.execute()
    ~~~~~~~~~~~^^
  File "C:\projetos\pyx3270\pyx3270\emulator.py", line 191, in execute
    return self.handle_result(result.decode('utf-8'))
           ~~~~~~~~~~~~~~~~~~^^^^^^^^^^^^^^^^^^^^^^^^
  File "C:\projetos\pyx3270\pyx3270\emulator.py", line 231, in handle_result
    raise CommandError(error_msg)
exceptions.CommandError: Wait(): Timed out
2025-05-29 10:32:43,008 - x3270_emulator - ERROR - Erro ao executar comando wait: Wait(): Timed out
Traceback (most recent call last):
  File "C:\projetos\pyx3270\pyx3270\emulator.py", line 725, in command_func
    cmd = self._exec_command(
        f'{name}({all_args})'.encode('utf8')
    )
  File "C:\projetos\pyx3270\pyx3270\emulator.py", line 795, in _exec_command
    cmd.execute()
    ~~~~~~~~~~~^^
  File "C:\projetos\pyx3270\pyx3270\emulator.py", line 191, in execute
    return self.handle_result(result.decode('utf-8'))
           ~~~~~~~~~~~~~~~~~~^^^^^^^^^^^^^^^^^^^^^^^^
  File "C:\projetos\pyx3270\pyx3270\emulator.py", line 231, in handle_result
    raise CommandError(error_msg)
exceptions.CommandError: Wait(): Timed out
2025-05-29 10:32:43,010 - x3270_emulator - WARNING - CommandError durante conexão: Wait(): Timed out
2025-05-29 10:32:43,488 - x3270_emulator - ERROR - Comando __iter__ não encontrado.
2025-05-29 10:33:46,124 - x3270_emulator - INFO - Inicializando X3270 (visible=True, model=2)
2025-05-29 10:33:46,125 - x3270_emulator - INFO - Criando aplicativo emulador
2025-05-29 10:33:46,125 - x3270_emulator - INFO - Criando Wc3270App (Windows, visível)
2025-05-29 10:33:46,125 - x3270_emulator - INFO - Inicializando Wc3270App com modelo: 2
2025-05-29 10:33:46,126 - x3270_emulator - INFO - Inicializando ExecutableApp (shell=True, model=2)
2025-05-29 10:33:46,338 - x3270_emulator - INFO - Processo iniciado com PID: 26896
2025-05-29 10:33:46,338 - x3270_emulator - INFO - Conectando ao host: localhost:992 (tls=False)
2025-05-29 10:33:46,338 - x3270_emulator - INFO - Conectando ao host: localhost:992
2025-05-29 10:33:46,633 - x3270_emulator - INFO - Processo iniciado com PID: 28024
2025-05-29 10:33:46,633 - x3270_emulator - INFO - Criando socket para porta 49327
2025-05-29 10:33:48,155 - x3270_emulator - INFO - Conexão de socket estabelecida com sucesso
2025-05-29 10:33:48,156 - x3270_emulator - INFO - Conexão estabelecida com sucesso
2025-05-29 10:33:48,156 - x3270_emulator - INFO - Executando comando wait com args=(5, '3270mode'), kwargs={}
2025-05-29 10:33:48,157 - x3270_emulator - INFO - Executando comando: b'wait(5, 3270mode)'
2025-05-29 10:33:53,171 - x3270_emulator - ERROR - Comando falhou: Wait(): Timed out
2025-05-29 10:33:53,171 - x3270_emulator - ERROR - Erro durante execução do comando: Wait(): Timed out
Traceback (most recent call last):
  File "C:\projetos\pyx3270\pyx3270\emulator.py", line 191, in execute
    return self.handle_result(result.decode('utf-8'))
           ~~~~~~~~~~~~~~~~~~^^^^^^^^^^^^^^^^^^^^^^^^
  File "C:\projetos\pyx3270\pyx3270\emulator.py", line 231, in handle_result
    raise CommandError(error_msg)
exceptions.CommandError: Wait(): Timed out
2025-05-29 10:33:53,176 - x3270_emulator - ERROR - Erro ao executar comando: Wait(): Timed out
Traceback (most recent call last):
  File "C:\projetos\pyx3270\pyx3270\emulator.py", line 795, in _exec_command
    cmd.execute()
    ~~~~~~~~~~~^^
  File "C:\projetos\pyx3270\pyx3270\emulator.py", line 191, in execute
    return self.handle_result(result.decode('utf-8'))
           ~~~~~~~~~~~~~~~~~~^^^^^^^^^^^^^^^^^^^^^^^^
  File "C:\projetos\pyx3270\pyx3270\emulator.py", line 231, in handle_result
    raise CommandError(error_msg)
exceptions.CommandError: Wait(): Timed out
2025-05-29 10:33:53,177 - x3270_emulator - ERROR - Erro ao executar comando wait: Wait(): Timed out
Traceback (most recent call last):
  File "C:\projetos\pyx3270\pyx3270\emulator.py", line 725, in command_func
    cmd = self._exec_command(
        f'{name}({all_args})'.encode('utf8')
    )
  File "C:\projetos\pyx3270\pyx3270\emulator.py", line 795, in _exec_command
    cmd.execute()
    ~~~~~~~~~~~^^
  File "C:\projetos\pyx3270\pyx3270\emulator.py", line 191, in execute
    return self.handle_result(result.decode('utf-8'))
           ~~~~~~~~~~~~~~~~~~^^^^^^^^^^^^^^^^^^^^^^^^
  File "C:\projetos\pyx3270\pyx3270\emulator.py", line 231, in handle_result
    raise CommandError(error_msg)
exceptions.CommandError: Wait(): Timed out
2025-05-29 10:33:53,178 - x3270_emulator - WARNING - CommandError durante conexão: Wait(): Timed out
2025-05-29 10:33:53,617 - x3270_emulator - ERROR - Comando __iter__ não encontrado.
2025-05-29 10:34:42,961 - x3270_emulator - INFO - Inicializando X3270 (visible=True, model=2)
2025-05-29 10:34:42,962 - x3270_emulator - INFO - Criando aplicativo emulador
2025-05-29 10:34:42,962 - x3270_emulator - INFO - Criando Wc3270App (Windows, visível)
2025-05-29 10:34:42,962 - x3270_emulator - INFO - Inicializando Wc3270App com modelo: 2
2025-05-29 10:34:42,963 - x3270_emulator - INFO - Inicializando ExecutableApp (shell=True, model=2)
2025-05-29 10:34:43,189 - x3270_emulator - INFO - Processo iniciado com PID: 11656
2025-05-29 10:34:43,189 - x3270_emulator - INFO - Conectando ao host: localhost:992 (tls=False)
2025-05-29 10:34:43,190 - x3270_emulator - INFO - Conectando ao host: localhost:992
2025-05-29 10:34:43,572 - x3270_emulator - INFO - Processo iniciado com PID: 27212
2025-05-29 10:34:43,572 - x3270_emulator - INFO - Criando socket para porta 49368
2025-05-29 10:34:45,120 - x3270_emulator - INFO - Conexão de socket estabelecida com sucesso
2025-05-29 10:34:45,121 - x3270_emulator - INFO - Conexão estabelecida com sucesso
2025-05-29 10:34:45,121 - x3270_emulator - INFO - Executando comando wait com args=(5, '3270mode'), kwargs={}
2025-05-29 10:34:45,121 - x3270_emulator - INFO - Executando comando: b'wait(5, 3270mode)'
2025-05-29 10:34:50,132 - x3270_emulator - ERROR - Comando falhou: Wait(): Timed out
2025-05-29 10:34:50,132 - x3270_emulator - ERROR - Erro durante execução do comando: Wait(): Timed out
Traceback (most recent call last):
  File "C:\projetos\pyx3270\pyx3270\emulator.py", line 191, in execute
    return self.handle_result(result.decode('utf-8'))
           ~~~~~~~~~~~~~~~~~~^^^^^^^^^^^^^^^^^^^^^^^^
  File "C:\projetos\pyx3270\pyx3270\emulator.py", line 231, in handle_result
    raise CommandError(error_msg)
exceptions.CommandError: Wait(): Timed out
2025-05-29 10:34:50,135 - x3270_emulator - ERROR - Erro ao executar comando: Wait(): Timed out
Traceback (most recent call last):
  File "C:\projetos\pyx3270\pyx3270\emulator.py", line 795, in _exec_command
    cmd.execute()
    ~~~~~~~~~~~^^
  File "C:\projetos\pyx3270\pyx3270\emulator.py", line 191, in execute
    return self.handle_result(result.decode('utf-8'))
           ~~~~~~~~~~~~~~~~~~^^^^^^^^^^^^^^^^^^^^^^^^
  File "C:\projetos\pyx3270\pyx3270\emulator.py", line 231, in handle_result
    raise CommandError(error_msg)
exceptions.CommandError: Wait(): Timed out
2025-05-29 10:34:50,136 - x3270_emulator - ERROR - Erro ao executar comando wait: Wait(): Timed out
Traceback (most recent call last):
  File "C:\projetos\pyx3270\pyx3270\emulator.py", line 725, in command_func
    cmd = self._exec_command(
        f'{name}({all_args})'.encode('utf8')
    )
  File "C:\projetos\pyx3270\pyx3270\emulator.py", line 795, in _exec_command
    cmd.execute()
    ~~~~~~~~~~~^^
  File "C:\projetos\pyx3270\pyx3270\emulator.py", line 191, in execute
    return self.handle_result(result.decode('utf-8'))
           ~~~~~~~~~~~~~~~~~~^^^^^^^^^^^^^^^^^^^^^^^^
  File "C:\projetos\pyx3270\pyx3270\emulator.py", line 231, in handle_result
    raise CommandError(error_msg)
exceptions.CommandError: Wait(): Timed out
2025-05-29 10:34:50,137 - x3270_emulator - WARNING - CommandError durante conexão: Wait(): Timed out
2025-05-29 10:34:50,576 - x3270_emulator - ERROR - Comando __iter__ não encontrado.
2025-05-29 16:20:00,422 - x3270_emulator - INFO - Inicializando X3270 (visible=True, model=2)
2025-05-29 16:20:00,422 - x3270_emulator - INFO - Criando aplicativo emulador
2025-05-29 16:20:00,423 - x3270_emulator - INFO - Criando Wc3270App (Windows, visível)
2025-05-29 16:20:00,423 - x3270_emulator - INFO - Inicializando Wc3270App com modelo: 2
2025-05-29 16:20:00,424 - x3270_emulator - INFO - Inicializando ExecutableApp (shell=True, model=2)
2025-05-29 16:20:00,590 - x3270_emulator - INFO - Processo iniciado com PID: 15192
2025-05-29 16:20:00,590 - x3270_emulator - INFO - Conectando ao host: localhost:992 (tls=False)
2025-05-29 16:20:00,590 - x3270_emulator - INFO - Conectando ao host: localhost:992
2025-05-29 16:20:00,868 - x3270_emulator - INFO - Processo iniciado com PID: 10804
2025-05-29 16:20:00,868 - x3270_emulator - INFO - Criando socket para porta 50297
2025-05-29 16:20:02,897 - x3270_emulator - INFO - Conexão de socket estabelecida com sucesso
2025-05-29 16:20:02,898 - x3270_emulator - INFO - Conexão estabelecida com sucesso
2025-05-29 16:20:02,898 - x3270_emulator - INFO - Executando comando wait com args=(5, '3270mode'), kwargs={}
2025-05-29 16:20:02,898 - x3270_emulator - INFO - Executando comando: b'wait(5, 3270mode)'
2025-05-29 16:20:07,914 - x3270_emulator - ERROR - Comando falhou: Wait(): Timed out
2025-05-29 16:20:07,915 - x3270_emulator - ERROR - Erro durante execução do comando: Wait(): Timed out
Traceback (most recent call last):
  File "C:\projetos\pyx3270\pyx3270\emulator.py", line 191, in execute
    return self.handle_result(result.decode('utf-8'))
           ~~~~~~~~~~~~~~~~~~^^^^^^^^^^^^^^^^^^^^^^^^
  File "C:\projetos\pyx3270\pyx3270\emulator.py", line 231, in handle_result
    raise CommandError(error_msg)
exceptions.CommandError: Wait(): Timed out
2025-05-29 16:20:07,922 - x3270_emulator - ERROR - Erro ao executar comando: Wait(): Timed out
Traceback (most recent call last):
  File "C:\projetos\pyx3270\pyx3270\emulator.py", line 793, in _exec_command
    cmd.execute()
    ~~~~~~~~~~~^^
  File "C:\projetos\pyx3270\pyx3270\emulator.py", line 191, in execute
    return self.handle_result(result.decode('utf-8'))
           ~~~~~~~~~~~~~~~~~~^^^^^^^^^^^^^^^^^^^^^^^^
  File "C:\projetos\pyx3270\pyx3270\emulator.py", line 231, in handle_result
    raise CommandError(error_msg)
exceptions.CommandError: Wait(): Timed out
2025-05-29 16:20:07,924 - x3270_emulator - ERROR - Erro ao executar comando wait: Wait(): Timed out
Traceback (most recent call last):
  File "C:\projetos\pyx3270\pyx3270\emulator.py", line 723, in command_func
    cmd = self._exec_command(
        f'{name}({all_args})'.encode('utf8')
    )
  File "C:\projetos\pyx3270\pyx3270\emulator.py", line 793, in _exec_command
    cmd.execute()
    ~~~~~~~~~~~^^
  File "C:\projetos\pyx3270\pyx3270\emulator.py", line 191, in execute
    return self.handle_result(result.decode('utf-8'))
           ~~~~~~~~~~~~~~~~~~^^^^^^^^^^^^^^^^^^^^^^^^
  File "C:\projetos\pyx3270\pyx3270\emulator.py", line 231, in handle_result
    raise CommandError(error_msg)
exceptions.CommandError: Wait(): Timed out
2025-05-29 16:20:07,925 - x3270_emulator - WARNING - CommandError durante conexão: Wait(): Timed out
2025-05-29 16:20:08,389 - x3270_emulator - ERROR - Comando __iter__ não encontrado.
2025-05-29 16:22:59,861 - x3270_emulator - INFO - Inicializando X3270 (visible=True, model=2)
2025-05-29 16:22:59,862 - x3270_emulator - INFO - Criando aplicativo emulador
2025-05-29 16:22:59,862 - x3270_emulator - INFO - Criando Wc3270App (Windows, visível)
2025-05-29 16:22:59,862 - x3270_emulator - INFO - Inicializando Wc3270App com modelo: 2
2025-05-29 16:22:59,863 - x3270_emulator - INFO - Inicializando ExecutableApp (shell=True, model=2)
2025-05-29 16:23:00,003 - x3270_emulator - INFO - Processo iniciado com PID: 24596
2025-05-29 16:23:00,003 - x3270_emulator - INFO - Conectando ao host: localhost:992 (tls=False)
2025-05-29 16:23:00,003 - x3270_emulator - INFO - Conectando ao host: localhost:992
2025-05-29 16:23:00,210 - x3270_emulator - INFO - Processo iniciado com PID: 8848
2025-05-29 16:23:00,210 - x3270_emulator - INFO - Criando socket para porta 50388
2025-05-29 16:23:01,760 - x3270_emulator - INFO - Conexão de socket estabelecida com sucesso
2025-05-29 16:23:01,761 - x3270_emulator - INFO - Conexão estabelecida com sucesso
2025-05-29 16:23:01,761 - x3270_emulator - INFO - Executando comando wait com args=(5, '3270mode'), kwargs={}
2025-05-29 16:23:01,762 - x3270_emulator - INFO - Executando comando: b'wait(5, 3270mode)'
2025-05-29 16:23:06,768 - x3270_emulator - ERROR - Comando falhou: Wait(): Timed out
2025-05-29 16:23:06,768 - x3270_emulator - ERROR - Erro durante execução do comando: Wait(): Timed out
Traceback (most recent call last):
  File "C:\projetos\pyx3270\pyx3270\emulator.py", line 191, in execute
    return self.handle_result(result.decode('utf-8'))
           ~~~~~~~~~~~~~~~~~~^^^^^^^^^^^^^^^^^^^^^^^^
  File "C:\projetos\pyx3270\pyx3270\emulator.py", line 231, in handle_result
    raise CommandError(error_msg)
exceptions.CommandError: Wait(): Timed out
2025-05-29 16:23:06,770 - x3270_emulator - ERROR - Erro ao executar comando: Wait(): Timed out
Traceback (most recent call last):
  File "C:\projetos\pyx3270\pyx3270\emulator.py", line 793, in _exec_command
    cmd.execute()
    ~~~~~~~~~~~^^
  File "C:\projetos\pyx3270\pyx3270\emulator.py", line 191, in execute
    return self.handle_result(result.decode('utf-8'))
           ~~~~~~~~~~~~~~~~~~^^^^^^^^^^^^^^^^^^^^^^^^
  File "C:\projetos\pyx3270\pyx3270\emulator.py", line 231, in handle_result
    raise CommandError(error_msg)
exceptions.CommandError: Wait(): Timed out
2025-05-29 16:23:06,771 - x3270_emulator - ERROR - Erro ao executar comando wait: Wait(): Timed out
Traceback (most recent call last):
  File "C:\projetos\pyx3270\pyx3270\emulator.py", line 723, in command_func
    cmd = self._exec_command(
        f'{name}({all_args})'.encode('utf8')
    )
  File "C:\projetos\pyx3270\pyx3270\emulator.py", line 793, in _exec_command
    cmd.execute()
    ~~~~~~~~~~~^^
  File "C:\projetos\pyx3270\pyx3270\emulator.py", line 191, in execute
    return self.handle_result(result.decode('utf-8'))
           ~~~~~~~~~~~~~~~~~~^^^^^^^^^^^^^^^^^^^^^^^^
  File "C:\projetos\pyx3270\pyx3270\emulator.py", line 231, in handle_result
    raise CommandError(error_msg)
exceptions.CommandError: Wait(): Timed out
2025-05-29 16:23:06,772 - x3270_emulator - WARNING - CommandError durante conexão: Wait(): Timed out
2025-05-29 16:24:17,144 - x3270_emulator - INFO - Inicializando X3270 (visible=True, model=2)
2025-05-29 16:24:17,144 - x3270_emulator - INFO - Criando aplicativo emulador
2025-05-29 16:24:17,145 - x3270_emulator - INFO - Criando Wc3270App (Windows, visível)
2025-05-29 16:24:17,145 - x3270_emulator - INFO - Inicializando Wc3270App com modelo: 2
2025-05-29 16:24:17,145 - x3270_emulator - INFO - Inicializando ExecutableApp (shell=True, model=2)
2025-05-29 16:24:17,341 - x3270_emulator - INFO - Processo iniciado com PID: 19716
2025-05-29 16:24:17,341 - x3270_emulator - INFO - Conectando ao host: localhost:992 (tls=False)
2025-05-29 16:24:17,341 - x3270_emulator - INFO - Conectando ao host: localhost:992
2025-05-29 16:24:17,547 - x3270_emulator - INFO - Processo iniciado com PID: 19844
2025-05-29 16:24:17,547 - x3270_emulator - INFO - Criando socket para porta 50445
2025-05-29 16:24:19,080 - x3270_emulator - INFO - Conexão de socket estabelecida com sucesso
2025-05-29 16:24:19,081 - x3270_emulator - INFO - Conexão estabelecida com sucesso
2025-05-29 16:24:19,082 - x3270_emulator - INFO - Executando comando wait com args=(5, '3270mode'), kwargs={}
2025-05-29 16:24:19,083 - x3270_emulator - INFO - Executando comando: b'wait(5, 3270mode)'
2025-05-29 16:24:24,095 - x3270_emulator - ERROR - Comando falhou: Wait(): Timed out
2025-05-29 16:24:24,095 - x3270_emulator - ERROR - Erro durante execução do comando: Wait(): Timed out
Traceback (most recent call last):
  File "C:\projetos\pyx3270\pyx3270\emulator.py", line 191, in execute
    return self.handle_result(result.decode('utf-8'))
           ~~~~~~~~~~~~~~~~~~^^^^^^^^^^^^^^^^^^^^^^^^
  File "C:\projetos\pyx3270\pyx3270\emulator.py", line 231, in handle_result
    raise CommandError(error_msg)
exceptions.CommandError: Wait(): Timed out
2025-05-29 16:24:24,104 - x3270_emulator - ERROR - Erro ao executar comando: Wait(): Timed out
Traceback (most recent call last):
  File "C:\projetos\pyx3270\pyx3270\emulator.py", line 793, in _exec_command
    cmd.execute()
    ~~~~~~~~~~~^^
  File "C:\projetos\pyx3270\pyx3270\emulator.py", line 191, in execute
    return self.handle_result(result.decode('utf-8'))
           ~~~~~~~~~~~~~~~~~~^^^^^^^^^^^^^^^^^^^^^^^^
  File "C:\projetos\pyx3270\pyx3270\emulator.py", line 231, in handle_result
    raise CommandError(error_msg)
exceptions.CommandError: Wait(): Timed out
2025-05-29 16:24:24,106 - x3270_emulator - ERROR - Erro ao executar comando wait: Wait(): Timed out
Traceback (most recent call last):
  File "C:\projetos\pyx3270\pyx3270\emulator.py", line 723, in command_func
    cmd = self._exec_command(
        f'{name}({all_args})'.encode('utf8')
    )
  File "C:\projetos\pyx3270\pyx3270\emulator.py", line 793, in _exec_command
    cmd.execute()
    ~~~~~~~~~~~^^
  File "C:\projetos\pyx3270\pyx3270\emulator.py", line 191, in execute
    return self.handle_result(result.decode('utf-8'))
           ~~~~~~~~~~~~~~~~~~^^^^^^^^^^^^^^^^^^^^^^^^
  File "C:\projetos\pyx3270\pyx3270\emulator.py", line 231, in handle_result
    raise CommandError(error_msg)
exceptions.CommandError: Wait(): Timed out
2025-05-29 16:24:24,109 - x3270_emulator - WARNING - CommandError durante conexão: Wait(): Timed out
2025-05-29 16:29:38,881 - x3270_emulator - INFO - Inicializando X3270 (visible=True, model=2)
2025-05-29 16:29:38,881 - x3270_emulator - INFO - Criando aplicativo emulador
2025-05-29 16:29:38,881 - x3270_emulator - INFO - Criando Wc3270App (Windows, visível)
2025-05-29 16:29:38,881 - x3270_emulator - INFO - Inicializando Wc3270App com modelo: 2
2025-05-29 16:29:38,882 - x3270_emulator - INFO - Inicializando ExecutableApp (shell=True, model=2)
2025-05-29 16:29:39,023 - x3270_emulator - INFO - Processo iniciado com PID: 17028
2025-05-29 16:29:39,023 - x3270_emulator - INFO - Conectando ao host: localhost:992 (tls=False)
2025-05-29 16:29:39,023 - x3270_emulator - INFO - Conectando ao host: localhost:992
2025-05-29 16:29:39,253 - x3270_emulator - INFO - Processo iniciado com PID: 21356
2025-05-29 16:29:39,254 - x3270_emulator - INFO - Criando socket para porta 50605
2025-05-29 16:29:40,776 - x3270_emulator - INFO - Conexão de socket estabelecida com sucesso
2025-05-29 16:29:40,776 - x3270_emulator - INFO - Conexão estabelecida com sucesso
2025-05-29 16:29:40,777 - x3270_emulator - INFO - Executando comando wait com args=(5, '3270mode'), kwargs={}
2025-05-29 16:29:40,777 - x3270_emulator - INFO - Executando comando: b'wait(5, 3270mode)'
2025-05-29 16:29:45,798 - x3270_emulator - ERROR - Comando falhou: Wait(): Timed out
2025-05-29 16:29:45,799 - x3270_emulator - ERROR - Erro durante execução do comando: Wait(): Timed out
Traceback (most recent call last):
  File "C:\projetos\pyx3270\pyx3270\emulator.py", line 191, in execute
    return self.handle_result(result.decode('utf-8'))
           ~~~~~~~~~~~~~~~~~~^^^^^^^^^^^^^^^^^^^^^^^^
  File "C:\projetos\pyx3270\pyx3270\emulator.py", line 231, in handle_result
    raise CommandError(error_msg)
exceptions.CommandError: Wait(): Timed out
2025-05-29 16:29:45,805 - x3270_emulator - ERROR - Erro ao executar comando: Wait(): Timed out
Traceback (most recent call last):
  File "C:\projetos\pyx3270\pyx3270\emulator.py", line 793, in _exec_command
    cmd.execute()
    ~~~~~~~~~~~^^
  File "C:\projetos\pyx3270\pyx3270\emulator.py", line 191, in execute
    return self.handle_result(result.decode('utf-8'))
           ~~~~~~~~~~~~~~~~~~^^^^^^^^^^^^^^^^^^^^^^^^
  File "C:\projetos\pyx3270\pyx3270\emulator.py", line 231, in handle_result
    raise CommandError(error_msg)
exceptions.CommandError: Wait(): Timed out
2025-05-29 16:29:45,808 - x3270_emulator - ERROR - Erro ao executar comando wait: Wait(): Timed out
Traceback (most recent call last):
  File "C:\projetos\pyx3270\pyx3270\emulator.py", line 723, in command_func
    cmd = self._exec_command(
        f'{name}({all_args})'.encode('utf8')
    )
  File "C:\projetos\pyx3270\pyx3270\emulator.py", line 793, in _exec_command
    cmd.execute()
    ~~~~~~~~~~~^^
  File "C:\projetos\pyx3270\pyx3270\emulator.py", line 191, in execute
    return self.handle_result(result.decode('utf-8'))
           ~~~~~~~~~~~~~~~~~~^^^^^^^^^^^^^^^^^^^^^^^^
  File "C:\projetos\pyx3270\pyx3270\emulator.py", line 231, in handle_result
    raise CommandError(error_msg)
exceptions.CommandError: Wait(): Timed out
2025-05-29 16:29:45,810 - x3270_emulator - WARNING - CommandError durante conexão: Wait(): Timed out
2025-05-29 16:32:14,672 - x3270_emulator - INFO - Inicializando X3270 (visible=True, model=2)
2025-05-29 16:32:14,675 - x3270_emulator - INFO - Criando aplicativo emulador
2025-05-29 16:32:14,675 - x3270_emulator - INFO - Criando Wc3270App (Windows, visível)
2025-05-29 16:32:14,675 - x3270_emulator - INFO - Inicializando Wc3270App com modelo: 2
2025-05-29 16:32:14,680 - x3270_emulator - INFO - Inicializando ExecutableApp (shell=True, model=2)
2025-05-29 16:32:14,824 - x3270_emulator - INFO - Processo iniciado com PID: 13800
2025-05-29 16:32:14,825 - x3270_emulator - INFO - Conectando ao host: localhost:992 (tls=False)
2025-05-29 16:32:14,825 - x3270_emulator - INFO - Conectando ao host: localhost:992
2025-05-29 16:32:14,966 - x3270_emulator - INFO - Processo iniciado com PID: 5540
2025-05-29 16:32:14,966 - x3270_emulator - INFO - Criando socket para porta 50696
2025-05-29 16:32:16,499 - x3270_emulator - INFO - Conexão de socket estabelecida com sucesso
2025-05-29 16:32:16,500 - x3270_emulator - INFO - Conexão estabelecida com sucesso
2025-05-29 16:32:16,500 - x3270_emulator - INFO - Executando comando wait com args=(5, '3270mode'), kwargs={}
2025-05-29 16:32:16,500 - x3270_emulator - INFO - Executando comando: b'wait(5, 3270mode)'
2025-05-29 16:32:21,512 - x3270_emulator - ERROR - Comando falhou: Wait(): Timed out
2025-05-29 16:32:21,513 - x3270_emulator - ERROR - Erro durante execução do comando: Wait(): Timed out
Traceback (most recent call last):
  File "C:\projetos\pyx3270\pyx3270\emulator.py", line 191, in execute
    return self.handle_result(result.decode('utf-8'))
           ~~~~~~~~~~~~~~~~~~^^^^^^^^^^^^^^^^^^^^^^^^
  File "C:\projetos\pyx3270\pyx3270\emulator.py", line 231, in handle_result
    raise CommandError(error_msg)
exceptions.CommandError: Wait(): Timed out
2025-05-29 16:32:21,518 - x3270_emulator - ERROR - Erro ao executar comando: Wait(): Timed out
Traceback (most recent call last):
  File "C:\projetos\pyx3270\pyx3270\emulator.py", line 793, in _exec_command
    cmd.execute()
    ~~~~~~~~~~~^^
  File "C:\projetos\pyx3270\pyx3270\emulator.py", line 191, in execute
    return self.handle_result(result.decode('utf-8'))
           ~~~~~~~~~~~~~~~~~~^^^^^^^^^^^^^^^^^^^^^^^^
  File "C:\projetos\pyx3270\pyx3270\emulator.py", line 231, in handle_result
    raise CommandError(error_msg)
exceptions.CommandError: Wait(): Timed out
2025-05-29 16:32:21,521 - x3270_emulator - ERROR - Erro ao executar comando wait: Wait(): Timed out
Traceback (most recent call last):
  File "C:\projetos\pyx3270\pyx3270\emulator.py", line 723, in command_func
    cmd = self._exec_command(
        f'{name}({all_args})'.encode('utf8')
    )
  File "C:\projetos\pyx3270\pyx3270\emulator.py", line 793, in _exec_command
    cmd.execute()
    ~~~~~~~~~~~^^
  File "C:\projetos\pyx3270\pyx3270\emulator.py", line 191, in execute
    return self.handle_result(result.decode('utf-8'))
           ~~~~~~~~~~~~~~~~~~^^^^^^^^^^^^^^^^^^^^^^^^
  File "C:\projetos\pyx3270\pyx3270\emulator.py", line 231, in handle_result
    raise CommandError(error_msg)
exceptions.CommandError: Wait(): Timed out
2025-05-29 16:32:21,523 - x3270_emulator - WARNING - CommandError durante conexão: Wait(): Timed out
2025-05-29 16:39:23,359 - x3270_emulator - INFO - Tentando reconectar ao host
2025-05-29 16:39:23,359 - x3270_emulator - INFO - Executando comando reconnect com args=(), kwargs={}
2025-05-29 16:39:23,360 - x3270_emulator - INFO - Executando comando: b'reconnect()'
2025-05-29 16:39:23,360 - x3270_emulator - ERROR - Erro de E/S ao escrever no socket: [WinError 10054] An existing connection was forcibly closed by the remote host
Traceback (most recent call last):
  File "C:\projetos\pyx3270\pyx3270\emulator.py", line 361, in write
    self.socket_fh.flush()
    ~~~~~~~~~~~~~~~~~~~~^^
  File "C:\Users\e5674469\.pyenv\pyenv-win\versions\3.13.1\Lib\socket.py", line 737, in write
    return self._sock.send(b)
           ~~~~~~~~~~~~~~~^^^
ConnectionResetError: [WinError 10054] An existing connection was forcibly closed by the remote host
2025-05-29 16:39:23,362 - x3270_emulator - ERROR - Erro durante execução do comando: 
Traceback (most recent call last):
  File "C:\projetos\pyx3270\pyx3270\emulator.py", line 361, in write
    self.socket_fh.flush()
    ~~~~~~~~~~~~~~~~~~~~^^
  File "C:\Users\e5674469\.pyenv\pyenv-win\versions\3.13.1\Lib\socket.py", line 737, in write
    return self._sock.send(b)
           ~~~~~~~~~~~~~~~^^^
ConnectionResetError: [WinError 10054] An existing connection was forcibly closed by the remote host

During handling of the above exception, another exception occurred:

Traceback (most recent call last):
  File "C:\projetos\pyx3270\pyx3270\emulator.py", line 182, in execute
    self.app.write(self.cmdstr + b'\n')
    ~~~~~~~~~~~~~~^^^^^^^^^^^^^^^^^^^^^
  File "C:\projetos\pyx3270\pyx3270\emulator.py", line 367, in write
    raise NotConnectedException
exceptions.NotConnectedException
2025-05-29 16:39:23,363 - x3270_emulator - ERROR - Erro ao executar comando: 
Traceback (most recent call last):
  File "C:\projetos\pyx3270\pyx3270\emulator.py", line 361, in write
    self.socket_fh.flush()
    ~~~~~~~~~~~~~~~~~~~~^^
  File "C:\Users\e5674469\.pyenv\pyenv-win\versions\3.13.1\Lib\socket.py", line 737, in write
    return self._sock.send(b)
           ~~~~~~~~~~~~~~~^^^
ConnectionResetError: [WinError 10054] An existing connection was forcibly closed by the remote host

During handling of the above exception, another exception occurred:

Traceback (most recent call last):
  File "C:\projetos\pyx3270\pyx3270\emulator.py", line 793, in _exec_command
    cmd.execute()
    ~~~~~~~~~~~^^
  File "C:\projetos\pyx3270\pyx3270\emulator.py", line 182, in execute
    self.app.write(self.cmdstr + b'\n')
    ~~~~~~~~~~~~~~^^^^^^^^^^^^^^^^^^^^^
  File "C:\projetos\pyx3270\pyx3270\emulator.py", line 367, in write
    raise NotConnectedException
exceptions.NotConnectedException
2025-05-29 16:39:23,366 - x3270_emulator - ERROR - Erro ao executar comando reconnect: 
Traceback (most recent call last):
  File "C:\projetos\pyx3270\pyx3270\emulator.py", line 361, in write
    self.socket_fh.flush()
    ~~~~~~~~~~~~~~~~~~~~^^
  File "C:\Users\e5674469\.pyenv\pyenv-win\versions\3.13.1\Lib\socket.py", line 737, in write
    return self._sock.send(b)
           ~~~~~~~~~~~~~~~^^^
ConnectionResetError: [WinError 10054] An existing connection was forcibly closed by the remote host

During handling of the above exception, another exception occurred:

Traceback (most recent call last):
  File "C:\projetos\pyx3270\pyx3270\emulator.py", line 723, in command_func
    cmd = self._exec_command(
        f'{name}({all_args})'.encode('utf8')
    )
  File "C:\projetos\pyx3270\pyx3270\emulator.py", line 793, in _exec_command
    cmd.execute()
    ~~~~~~~~~~~^^
  File "C:\projetos\pyx3270\pyx3270\emulator.py", line 182, in execute
    self.app.write(self.cmdstr + b'\n')
    ~~~~~~~~~~~~~~^^^^^^^^^^^^^^^^^^^^^
  File "C:\projetos\pyx3270\pyx3270\emulator.py", line 367, in write
    raise NotConnectedException
exceptions.NotConnectedException
2025-05-29 16:39:23,367 - x3270_emulator - WARNING - Erro durante reconexão: 
Traceback (most recent call last):
  File "C:\projetos\pyx3270\pyx3270\emulator.py", line 361, in write
    self.socket_fh.flush()
    ~~~~~~~~~~~~~~~~~~~~^^
  File "C:\Users\e5674469\.pyenv\pyenv-win\versions\3.13.1\Lib\socket.py", line 737, in write
    return self._sock.send(b)
           ~~~~~~~~~~~~~~~^^^
ConnectionResetError: [WinError 10054] An existing connection was forcibly closed by the remote host

During handling of the above exception, another exception occurred:

Traceback (most recent call last):
  File "C:\projetos\pyx3270\pyx3270\emulator.py", line 864, in reconnect_host
    self.reconnect()
    ~~~~~~~~~~~~~~^^
  File "C:\projetos\pyx3270\pyx3270\emulator.py", line 723, in command_func
    cmd = self._exec_command(
        f'{name}({all_args})'.encode('utf8')
    )
  File "C:\projetos\pyx3270\pyx3270\emulator.py", line 793, in _exec_command
    cmd.execute()
    ~~~~~~~~~~~^^
  File "C:\projetos\pyx3270\pyx3270\emulator.py", line 182, in execute
    self.app.write(self.cmdstr + b'\n')
    ~~~~~~~~~~~~~~^^^^^^^^^^^^^^^^^^^^^
  File "C:\projetos\pyx3270\pyx3270\emulator.py", line 367, in write
    raise NotConnectedException
exceptions.NotConnectedException
2025-05-29 16:39:23,368 - x3270_emulator - INFO - Terminando emulador
2025-05-29 16:39:23,368 - x3270_emulator - INFO - Executando comando quit com args=(), kwargs={}
2025-05-29 16:39:23,368 - x3270_emulator - INFO - Executando comando: b'quit()'
2025-05-29 16:39:23,369 - x3270_emulator - ERROR - Erro de E/S ao escrever no socket: [WinError 10054] An existing connection was forcibly closed by the remote host
Traceback (most recent call last):
  File "C:\projetos\pyx3270\pyx3270\emulator.py", line 361, in write
    self.socket_fh.flush()
    ~~~~~~~~~~~~~~~~~~~~^^
  File "C:\Users\e5674469\.pyenv\pyenv-win\versions\3.13.1\Lib\socket.py", line 737, in write
    return self._sock.send(b)
           ~~~~~~~~~~~~~~~^^^
ConnectionResetError: [WinError 10054] An existing connection was forcibly closed by the remote host

During handling of the above exception, another exception occurred:

Traceback (most recent call last):
  File "C:\projetos\pyx3270\pyx3270\emulator.py", line 864, in reconnect_host
    self.reconnect()
    ~~~~~~~~~~~~~~^^
  File "C:\projetos\pyx3270\pyx3270\emulator.py", line 723, in command_func
    cmd = self._exec_command(
        f'{name}({all_args})'.encode('utf8')
    )
  File "C:\projetos\pyx3270\pyx3270\emulator.py", line 793, in _exec_command
    cmd.execute()
    ~~~~~~~~~~~^^
  File "C:\projetos\pyx3270\pyx3270\emulator.py", line 182, in execute
    self.app.write(self.cmdstr + b'\n')
    ~~~~~~~~~~~~~~^^^^^^^^^^^^^^^^^^^^^
  File "C:\projetos\pyx3270\pyx3270\emulator.py", line 367, in write
    raise NotConnectedException
exceptions.NotConnectedException

During handling of the above exception, another exception occurred:

Traceback (most recent call last):
  File "C:\projetos\pyx3270\pyx3270\emulator.py", line 361, in write
    self.socket_fh.flush()
    ~~~~~~~~~~~~~~~~~~~~^^
  File "C:\Users\e5674469\.pyenv\pyenv-win\versions\3.13.1\Lib\socket.py", line 737, in write
    return self._sock.send(b)
           ~~~~~~~~~~~~~~~^^^
ConnectionResetError: [WinError 10054] An existing connection was forcibly closed by the remote host
2025-05-29 16:39:23,371 - x3270_emulator - ERROR - Erro durante execução do comando: 
Traceback (most recent call last):
  File "C:\projetos\pyx3270\pyx3270\emulator.py", line 361, in write
    self.socket_fh.flush()
    ~~~~~~~~~~~~~~~~~~~~^^
  File "C:\Users\e5674469\.pyenv\pyenv-win\versions\3.13.1\Lib\socket.py", line 737, in write
    return self._sock.send(b)
           ~~~~~~~~~~~~~~~^^^
ConnectionResetError: [WinError 10054] An existing connection was forcibly closed by the remote host

During handling of the above exception, another exception occurred:

Traceback (most recent call last):
  File "C:\projetos\pyx3270\pyx3270\emulator.py", line 864, in reconnect_host
    self.reconnect()
    ~~~~~~~~~~~~~~^^
  File "C:\projetos\pyx3270\pyx3270\emulator.py", line 723, in command_func
    cmd = self._exec_command(
        f'{name}({all_args})'.encode('utf8')
    )
  File "C:\projetos\pyx3270\pyx3270\emulator.py", line 793, in _exec_command
    cmd.execute()
    ~~~~~~~~~~~^^
  File "C:\projetos\pyx3270\pyx3270\emulator.py", line 182, in execute
    self.app.write(self.cmdstr + b'\n')
    ~~~~~~~~~~~~~~^^^^^^^^^^^^^^^^^^^^^
  File "C:\projetos\pyx3270\pyx3270\emulator.py", line 367, in write
    raise NotConnectedException
exceptions.NotConnectedException

During handling of the above exception, another exception occurred:

Traceback (most recent call last):
  File "C:\projetos\pyx3270\pyx3270\emulator.py", line 361, in write
    self.socket_fh.flush()
    ~~~~~~~~~~~~~~~~~~~~^^
  File "C:\Users\e5674469\.pyenv\pyenv-win\versions\3.13.1\Lib\socket.py", line 737, in write
    return self._sock.send(b)
           ~~~~~~~~~~~~~~~^^^
ConnectionResetError: [WinError 10054] An existing connection was forcibly closed by the remote host

During handling of the above exception, another exception occurred:

Traceback (most recent call last):
  File "C:\projetos\pyx3270\pyx3270\emulator.py", line 182, in execute
    self.app.write(self.cmdstr + b'\n')
    ~~~~~~~~~~~~~~^^^^^^^^^^^^^^^^^^^^^
  File "C:\projetos\pyx3270\pyx3270\emulator.py", line 367, in write
    raise NotConnectedException
exceptions.NotConnectedException
2025-05-29 16:39:23,373 - x3270_emulator - ERROR - Erro ao executar comando: 
Traceback (most recent call last):
  File "C:\projetos\pyx3270\pyx3270\emulator.py", line 361, in write
    self.socket_fh.flush()
    ~~~~~~~~~~~~~~~~~~~~^^
  File "C:\Users\e5674469\.pyenv\pyenv-win\versions\3.13.1\Lib\socket.py", line 737, in write
    return self._sock.send(b)
           ~~~~~~~~~~~~~~~^^^
ConnectionResetError: [WinError 10054] An existing connection was forcibly closed by the remote host

During handling of the above exception, another exception occurred:

Traceback (most recent call last):
  File "C:\projetos\pyx3270\pyx3270\emulator.py", line 864, in reconnect_host
    self.reconnect()
    ~~~~~~~~~~~~~~^^
  File "C:\projetos\pyx3270\pyx3270\emulator.py", line 723, in command_func
    cmd = self._exec_command(
        f'{name}({all_args})'.encode('utf8')
    )
  File "C:\projetos\pyx3270\pyx3270\emulator.py", line 793, in _exec_command
    cmd.execute()
    ~~~~~~~~~~~^^
  File "C:\projetos\pyx3270\pyx3270\emulator.py", line 182, in execute
    self.app.write(self.cmdstr + b'\n')
    ~~~~~~~~~~~~~~^^^^^^^^^^^^^^^^^^^^^
  File "C:\projetos\pyx3270\pyx3270\emulator.py", line 367, in write
    raise NotConnectedException
exceptions.NotConnectedException

During handling of the above exception, another exception occurred:

Traceback (most recent call last):
  File "C:\projetos\pyx3270\pyx3270\emulator.py", line 361, in write
    self.socket_fh.flush()
    ~~~~~~~~~~~~~~~~~~~~^^
  File "C:\Users\e5674469\.pyenv\pyenv-win\versions\3.13.1\Lib\socket.py", line 737, in write
    return self._sock.send(b)
           ~~~~~~~~~~~~~~~^^^
ConnectionResetError: [WinError 10054] An existing connection was forcibly closed by the remote host

During handling of the above exception, another exception occurred:

Traceback (most recent call last):
  File "C:\projetos\pyx3270\pyx3270\emulator.py", line 793, in _exec_command
    cmd.execute()
    ~~~~~~~~~~~^^
  File "C:\projetos\pyx3270\pyx3270\emulator.py", line 182, in execute
    self.app.write(self.cmdstr + b'\n')
    ~~~~~~~~~~~~~~^^^^^^^^^^^^^^^^^^^^^
  File "C:\projetos\pyx3270\pyx3270\emulator.py", line 367, in write
    raise NotConnectedException
exceptions.NotConnectedException
2025-05-29 16:39:23,376 - x3270_emulator - ERROR - Erro ao executar comando quit: 
Traceback (most recent call last):
  File "C:\projetos\pyx3270\pyx3270\emulator.py", line 361, in write
    self.socket_fh.flush()
    ~~~~~~~~~~~~~~~~~~~~^^
  File "C:\Users\e5674469\.pyenv\pyenv-win\versions\3.13.1\Lib\socket.py", line 737, in write
    return self._sock.send(b)
           ~~~~~~~~~~~~~~~^^^
ConnectionResetError: [WinError 10054] An existing connection was forcibly closed by the remote host

During handling of the above exception, another exception occurred:

Traceback (most recent call last):
  File "C:\projetos\pyx3270\pyx3270\emulator.py", line 864, in reconnect_host
    self.reconnect()
    ~~~~~~~~~~~~~~^^
  File "C:\projetos\pyx3270\pyx3270\emulator.py", line 723, in command_func
    cmd = self._exec_command(
        f'{name}({all_args})'.encode('utf8')
    )
  File "C:\projetos\pyx3270\pyx3270\emulator.py", line 793, in _exec_command
    cmd.execute()
    ~~~~~~~~~~~^^
  File "C:\projetos\pyx3270\pyx3270\emulator.py", line 182, in execute
    self.app.write(self.cmdstr + b'\n')
    ~~~~~~~~~~~~~~^^^^^^^^^^^^^^^^^^^^^
  File "C:\projetos\pyx3270\pyx3270\emulator.py", line 367, in write
    raise NotConnectedException
exceptions.NotConnectedException

During handling of the above exception, another exception occurred:

Traceback (most recent call last):
  File "C:\projetos\pyx3270\pyx3270\emulator.py", line 361, in write
    self.socket_fh.flush()
    ~~~~~~~~~~~~~~~~~~~~^^
  File "C:\Users\e5674469\.pyenv\pyenv-win\versions\3.13.1\Lib\socket.py", line 737, in write
    return self._sock.send(b)
           ~~~~~~~~~~~~~~~^^^
ConnectionResetError: [WinError 10054] An existing connection was forcibly closed by the remote host

During handling of the above exception, another exception occurred:

Traceback (most recent call last):
  File "C:\projetos\pyx3270\pyx3270\emulator.py", line 723, in command_func
    cmd = self._exec_command(
        f'{name}({all_args})'.encode('utf8')
    )
  File "C:\projetos\pyx3270\pyx3270\emulator.py", line 793, in _exec_command
    cmd.execute()
    ~~~~~~~~~~~^^
  File "C:\projetos\pyx3270\pyx3270\emulator.py", line 182, in execute
    self.app.write(self.cmdstr + b'\n')
    ~~~~~~~~~~~~~~^^^^^^^^^^^^^^^^^^^^^
  File "C:\projetos\pyx3270\pyx3270\emulator.py", line 367, in write
    raise NotConnectedException
exceptions.NotConnectedException
2025-05-29 16:39:23,378 - x3270_emulator - INFO - Criando nova instância para reconexão
2025-05-29 16:39:23,378 - x3270_emulator - INFO - Inicializando X3270 (visible=True, model=2)
2025-05-29 16:39:23,378 - x3270_emulator - INFO - Criando aplicativo emulador
2025-05-29 16:39:23,378 - x3270_emulator - INFO - Criando Wc3270App (Windows, visível)
2025-05-29 16:39:23,378 - x3270_emulator - INFO - Inicializando Wc3270App com modelo: 2
2025-05-29 16:39:23,380 - x3270_emulator - INFO - Inicializando ExecutableApp (shell=True, model=2)
2025-05-29 16:39:23,524 - x3270_emulator - INFO - Processo iniciado com PID: 9616
2025-05-29 16:39:23,524 - x3270_emulator - INFO - Conectando ao host: localhost:992 (tls=False)
2025-05-29 16:39:23,524 - x3270_emulator - INFO - Conectando ao host: localhost:992
2025-05-29 16:39:23,667 - x3270_emulator - INFO - Processo iniciado com PID: 9296
2025-05-29 16:39:23,667 - x3270_emulator - INFO - Criando socket para porta 59084
2025-05-29 16:39:25,196 - x3270_emulator - INFO - Conexão de socket estabelecida com sucesso
2025-05-29 16:39:25,197 - x3270_emulator - INFO - Conexão estabelecida com sucesso
2025-05-29 16:39:25,197 - x3270_emulator - INFO - Executando comando wait com args=(5, '3270mode'), kwargs={}
2025-05-29 16:39:25,197 - x3270_emulator - INFO - Executando comando: b'wait(5, 3270mode)'
2025-05-29 16:39:30,112 - x3270_emulator - ERROR - Erro ao ler do socket: [WinError 10054] An existing connection was forcibly closed by the remote host
Traceback (most recent call last):
  File "C:\projetos\pyx3270\pyx3270\emulator.py", line 361, in write
    self.socket_fh.flush()
    ~~~~~~~~~~~~~~~~~~~~^^
  File "C:\Users\e5674469\.pyenv\pyenv-win\versions\3.13.1\Lib\socket.py", line 737, in write
    return self._sock.send(b)
           ~~~~~~~~~~~~~~~^^^
ConnectionResetError: [WinError 10054] An existing connection was forcibly closed by the remote host

During handling of the above exception, another exception occurred:

Traceback (most recent call last):
  File "C:\projetos\pyx3270\pyx3270\emulator.py", line 864, in reconnect_host
    self.reconnect()
    ~~~~~~~~~~~~~~^^
  File "C:\projetos\pyx3270\pyx3270\emulator.py", line 723, in command_func
    cmd = self._exec_command(
        f'{name}({all_args})'.encode('utf8')
    )
  File "C:\projetos\pyx3270\pyx3270\emulator.py", line 793, in _exec_command
    cmd.execute()
    ~~~~~~~~~~~^^
  File "C:\projetos\pyx3270\pyx3270\emulator.py", line 182, in execute
    self.app.write(self.cmdstr + b'\n')
    ~~~~~~~~~~~~~~^^^^^^^^^^^^^^^^^^^^^
  File "C:\projetos\pyx3270\pyx3270\emulator.py", line 367, in write
    raise NotConnectedException
exceptions.NotConnectedException

During handling of the above exception, another exception occurred:

Traceback (most recent call last):
  File "C:\projetos\pyx3270\pyx3270\emulator.py", line 361, in write
    self.socket_fh.flush()
    ~~~~~~~~~~~~~~~~~~~~^^
  File "C:\Users\e5674469\.pyenv\pyenv-win\versions\3.13.1\Lib\socket.py", line 737, in write
    return self._sock.send(b)
           ~~~~~~~~~~~~~~~^^^
ConnectionResetError: [WinError 10054] An existing connection was forcibly closed by the remote host

During handling of the above exception, another exception occurred:

Traceback (most recent call last):
  File "C:\projetos\pyx3270\pyx3270\emulator.py", line 870, in reconnect_host
    self.terminate()
    ~~~~~~~~~~~~~~^^
  File "C:\projetos\pyx3270\pyx3270\emulator.py", line 806, in terminate
    self.quit()
    ~~~~~~~~~^^
  File "C:\projetos\pyx3270\pyx3270\emulator.py", line 723, in command_func
    cmd = self._exec_command(
        f'{name}({all_args})'.encode('utf8')
    )
  File "C:\projetos\pyx3270\pyx3270\emulator.py", line 793, in _exec_command
    cmd.execute()
    ~~~~~~~~~~~^^
  File "C:\projetos\pyx3270\pyx3270\emulator.py", line 182, in execute
    self.app.write(self.cmdstr + b'\n')
    ~~~~~~~~~~~~~~^^^^^^^^^^^^^^^^^^^^^
  File "C:\projetos\pyx3270\pyx3270\emulator.py", line 367, in write
    raise NotConnectedException
exceptions.NotConnectedException

During handling of the above exception, another exception occurred:

Traceback (most recent call last):
  File "C:\projetos\pyx3270\pyx3270\emulator.py", line 375, in readline
    line = self.socket_fh.readline()
  File "C:\Users\e5674469\.pyenv\pyenv-win\versions\3.13.1\Lib\socket.py", line 719, in readinto
    return self._sock.recv_into(b)
           ~~~~~~~~~~~~~~~~~~~~^^^
ConnectionResetError: [WinError 10054] An existing connection was forcibly closed by the remote host
2025-05-29 16:39:30,118 - x3270_emulator - ERROR - Erro durante execução do comando: 
Traceback (most recent call last):
  File "C:\projetos\pyx3270\pyx3270\emulator.py", line 361, in write
    self.socket_fh.flush()
    ~~~~~~~~~~~~~~~~~~~~^^
  File "C:\Users\e5674469\.pyenv\pyenv-win\versions\3.13.1\Lib\socket.py", line 737, in write
    return self._sock.send(b)
           ~~~~~~~~~~~~~~~^^^
ConnectionResetError: [WinError 10054] An existing connection was forcibly closed by the remote host

During handling of the above exception, another exception occurred:

Traceback (most recent call last):
  File "C:\projetos\pyx3270\pyx3270\emulator.py", line 864, in reconnect_host
    self.reconnect()
    ~~~~~~~~~~~~~~^^
  File "C:\projetos\pyx3270\pyx3270\emulator.py", line 723, in command_func
    cmd = self._exec_command(
        f'{name}({all_args})'.encode('utf8')
    )
  File "C:\projetos\pyx3270\pyx3270\emulator.py", line 793, in _exec_command
    cmd.execute()
    ~~~~~~~~~~~^^
  File "C:\projetos\pyx3270\pyx3270\emulator.py", line 182, in execute
    self.app.write(self.cmdstr + b'\n')
    ~~~~~~~~~~~~~~^^^^^^^^^^^^^^^^^^^^^
  File "C:\projetos\pyx3270\pyx3270\emulator.py", line 367, in write
    raise NotConnectedException
exceptions.NotConnectedException

During handling of the above exception, another exception occurred:

Traceback (most recent call last):
  File "C:\projetos\pyx3270\pyx3270\emulator.py", line 361, in write
    self.socket_fh.flush()
    ~~~~~~~~~~~~~~~~~~~~^^
  File "C:\Users\e5674469\.pyenv\pyenv-win\versions\3.13.1\Lib\socket.py", line 737, in write
    return self._sock.send(b)
           ~~~~~~~~~~~~~~~^^^
ConnectionResetError: [WinError 10054] An existing connection was forcibly closed by the remote host

During handling of the above exception, another exception occurred:

Traceback (most recent call last):
  File "C:\projetos\pyx3270\pyx3270\emulator.py", line 870, in reconnect_host
    self.terminate()
    ~~~~~~~~~~~~~~^^
  File "C:\projetos\pyx3270\pyx3270\emulator.py", line 806, in terminate
    self.quit()
    ~~~~~~~~~^^
  File "C:\projetos\pyx3270\pyx3270\emulator.py", line 723, in command_func
    cmd = self._exec_command(
        f'{name}({all_args})'.encode('utf8')
    )
  File "C:\projetos\pyx3270\pyx3270\emulator.py", line 793, in _exec_command
    cmd.execute()
    ~~~~~~~~~~~^^
  File "C:\projetos\pyx3270\pyx3270\emulator.py", line 182, in execute
    self.app.write(self.cmdstr + b'\n')
    ~~~~~~~~~~~~~~^^^^^^^^^^^^^^^^^^^^^
  File "C:\projetos\pyx3270\pyx3270\emulator.py", line 367, in write
    raise NotConnectedException
exceptions.NotConnectedException

During handling of the above exception, another exception occurred:

Traceback (most recent call last):
  File "C:\projetos\pyx3270\pyx3270\emulator.py", line 375, in readline
    line = self.socket_fh.readline()
  File "C:\Users\e5674469\.pyenv\pyenv-win\versions\3.13.1\Lib\socket.py", line 719, in readinto
    return self._sock.recv_into(b)
           ~~~~~~~~~~~~~~~~~~~~^^^
ConnectionResetError: [WinError 10054] An existing connection was forcibly closed by the remote host

During handling of the above exception, another exception occurred:

Traceback (most recent call last):
  File "C:\projetos\pyx3270\pyx3270\emulator.py", line 185, in execute
    line = self.app.readline()
  File "C:\projetos\pyx3270\pyx3270\emulator.py", line 380, in readline
    raise NotConnectedException
exceptions.NotConnectedException
2025-05-29 16:39:30,122 - x3270_emulator - ERROR - Erro ao executar comando: 
Traceback (most recent call last):
  File "C:\projetos\pyx3270\pyx3270\emulator.py", line 361, in write
    self.socket_fh.flush()
    ~~~~~~~~~~~~~~~~~~~~^^
  File "C:\Users\e5674469\.pyenv\pyenv-win\versions\3.13.1\Lib\socket.py", line 737, in write
    return self._sock.send(b)
           ~~~~~~~~~~~~~~~^^^
ConnectionResetError: [WinError 10054] An existing connection was forcibly closed by the remote host

During handling of the above exception, another exception occurred:

Traceback (most recent call last):
  File "C:\projetos\pyx3270\pyx3270\emulator.py", line 864, in reconnect_host
    self.reconnect()
    ~~~~~~~~~~~~~~^^
  File "C:\projetos\pyx3270\pyx3270\emulator.py", line 723, in command_func
    cmd = self._exec_command(
        f'{name}({all_args})'.encode('utf8')
    )
  File "C:\projetos\pyx3270\pyx3270\emulator.py", line 793, in _exec_command
    cmd.execute()
    ~~~~~~~~~~~^^
  File "C:\projetos\pyx3270\pyx3270\emulator.py", line 182, in execute
    self.app.write(self.cmdstr + b'\n')
    ~~~~~~~~~~~~~~^^^^^^^^^^^^^^^^^^^^^
  File "C:\projetos\pyx3270\pyx3270\emulator.py", line 367, in write
    raise NotConnectedException
exceptions.NotConnectedException

During handling of the above exception, another exception occurred:

Traceback (most recent call last):
  File "C:\projetos\pyx3270\pyx3270\emulator.py", line 361, in write
    self.socket_fh.flush()
    ~~~~~~~~~~~~~~~~~~~~^^
  File "C:\Users\e5674469\.pyenv\pyenv-win\versions\3.13.1\Lib\socket.py", line 737, in write
    return self._sock.send(b)
           ~~~~~~~~~~~~~~~^^^
ConnectionResetError: [WinError 10054] An existing connection was forcibly closed by the remote host

During handling of the above exception, another exception occurred:

Traceback (most recent call last):
  File "C:\projetos\pyx3270\pyx3270\emulator.py", line 870, in reconnect_host
    self.terminate()
    ~~~~~~~~~~~~~~^^
  File "C:\projetos\pyx3270\pyx3270\emulator.py", line 806, in terminate
    self.quit()
    ~~~~~~~~~^^
  File "C:\projetos\pyx3270\pyx3270\emulator.py", line 723, in command_func
    cmd = self._exec_command(
        f'{name}({all_args})'.encode('utf8')
    )
  File "C:\projetos\pyx3270\pyx3270\emulator.py", line 793, in _exec_command
    cmd.execute()
    ~~~~~~~~~~~^^
  File "C:\projetos\pyx3270\pyx3270\emulator.py", line 182, in execute
    self.app.write(self.cmdstr + b'\n')
    ~~~~~~~~~~~~~~^^^^^^^^^^^^^^^^^^^^^
  File "C:\projetos\pyx3270\pyx3270\emulator.py", line 367, in write
    raise NotConnectedException
exceptions.NotConnectedException

During handling of the above exception, another exception occurred:

Traceback (most recent call last):
  File "C:\projetos\pyx3270\pyx3270\emulator.py", line 375, in readline
    line = self.socket_fh.readline()
  File "C:\Users\e5674469\.pyenv\pyenv-win\versions\3.13.1\Lib\socket.py", line 719, in readinto
    return self._sock.recv_into(b)
           ~~~~~~~~~~~~~~~~~~~~^^^
ConnectionResetError: [WinError 10054] An existing connection was forcibly closed by the remote host

During handling of the above exception, another exception occurred:

Traceback (most recent call last):
  File "C:\projetos\pyx3270\pyx3270\emulator.py", line 793, in _exec_command
    cmd.execute()
    ~~~~~~~~~~~^^
  File "C:\projetos\pyx3270\pyx3270\emulator.py", line 185, in execute
    line = self.app.readline()
  File "C:\projetos\pyx3270\pyx3270\emulator.py", line 380, in readline
    raise NotConnectedException
exceptions.NotConnectedException
2025-05-29 16:39:30,127 - x3270_emulator - ERROR - Erro ao executar comando wait: 
Traceback (most recent call last):
  File "C:\projetos\pyx3270\pyx3270\emulator.py", line 361, in write
    self.socket_fh.flush()
    ~~~~~~~~~~~~~~~~~~~~^^
  File "C:\Users\e5674469\.pyenv\pyenv-win\versions\3.13.1\Lib\socket.py", line 737, in write
    return self._sock.send(b)
           ~~~~~~~~~~~~~~~^^^
ConnectionResetError: [WinError 10054] An existing connection was forcibly closed by the remote host

During handling of the above exception, another exception occurred:

Traceback (most recent call last):
  File "C:\projetos\pyx3270\pyx3270\emulator.py", line 864, in reconnect_host
    self.reconnect()
    ~~~~~~~~~~~~~~^^
  File "C:\projetos\pyx3270\pyx3270\emulator.py", line 723, in command_func
    cmd = self._exec_command(
        f'{name}({all_args})'.encode('utf8')
    )
  File "C:\projetos\pyx3270\pyx3270\emulator.py", line 793, in _exec_command
    cmd.execute()
    ~~~~~~~~~~~^^
  File "C:\projetos\pyx3270\pyx3270\emulator.py", line 182, in execute
    self.app.write(self.cmdstr + b'\n')
    ~~~~~~~~~~~~~~^^^^^^^^^^^^^^^^^^^^^
  File "C:\projetos\pyx3270\pyx3270\emulator.py", line 367, in write
    raise NotConnectedException
exceptions.NotConnectedException

During handling of the above exception, another exception occurred:

Traceback (most recent call last):
  File "C:\projetos\pyx3270\pyx3270\emulator.py", line 361, in write
    self.socket_fh.flush()
    ~~~~~~~~~~~~~~~~~~~~^^
  File "C:\Users\e5674469\.pyenv\pyenv-win\versions\3.13.1\Lib\socket.py", line 737, in write
    return self._sock.send(b)
           ~~~~~~~~~~~~~~~^^^
ConnectionResetError: [WinError 10054] An existing connection was forcibly closed by the remote host

During handling of the above exception, another exception occurred:

Traceback (most recent call last):
  File "C:\projetos\pyx3270\pyx3270\emulator.py", line 870, in reconnect_host
    self.terminate()
    ~~~~~~~~~~~~~~^^
  File "C:\projetos\pyx3270\pyx3270\emulator.py", line 806, in terminate
    self.quit()
    ~~~~~~~~~^^
  File "C:\projetos\pyx3270\pyx3270\emulator.py", line 723, in command_func
    cmd = self._exec_command(
        f'{name}({all_args})'.encode('utf8')
    )
  File "C:\projetos\pyx3270\pyx3270\emulator.py", line 793, in _exec_command
    cmd.execute()
    ~~~~~~~~~~~^^
  File "C:\projetos\pyx3270\pyx3270\emulator.py", line 182, in execute
    self.app.write(self.cmdstr + b'\n')
    ~~~~~~~~~~~~~~^^^^^^^^^^^^^^^^^^^^^
  File "C:\projetos\pyx3270\pyx3270\emulator.py", line 367, in write
    raise NotConnectedException
exceptions.NotConnectedException

During handling of the above exception, another exception occurred:

Traceback (most recent call last):
  File "C:\projetos\pyx3270\pyx3270\emulator.py", line 375, in readline
    line = self.socket_fh.readline()
  File "C:\Users\e5674469\.pyenv\pyenv-win\versions\3.13.1\Lib\socket.py", line 719, in readinto
    return self._sock.recv_into(b)
           ~~~~~~~~~~~~~~~~~~~~^^^
ConnectionResetError: [WinError 10054] An existing connection was forcibly closed by the remote host

During handling of the above exception, another exception occurred:

Traceback (most recent call last):
  File "C:\projetos\pyx3270\pyx3270\emulator.py", line 723, in command_func
    cmd = self._exec_command(
        f'{name}({all_args})'.encode('utf8')
    )
  File "C:\projetos\pyx3270\pyx3270\emulator.py", line 793, in _exec_command
    cmd.execute()
    ~~~~~~~~~~~^^
  File "C:\projetos\pyx3270\pyx3270\emulator.py", line 185, in execute
    line = self.app.readline()
  File "C:\projetos\pyx3270\pyx3270\emulator.py", line 380, in readline
    raise NotConnectedException
exceptions.NotConnectedException
2025-05-29 16:39:30,136 - x3270_emulator - ERROR - Erro ao conectar: 
Traceback (most recent call last):
  File "C:\projetos\pyx3270\pyx3270\emulator.py", line 361, in write
    self.socket_fh.flush()
    ~~~~~~~~~~~~~~~~~~~~^^
  File "C:\Users\e5674469\.pyenv\pyenv-win\versions\3.13.1\Lib\socket.py", line 737, in write
    return self._sock.send(b)
           ~~~~~~~~~~~~~~~^^^
ConnectionResetError: [WinError 10054] An existing connection was forcibly closed by the remote host

During handling of the above exception, another exception occurred:

Traceback (most recent call last):
  File "C:\projetos\pyx3270\pyx3270\emulator.py", line 864, in reconnect_host
    self.reconnect()
    ~~~~~~~~~~~~~~^^
  File "C:\projetos\pyx3270\pyx3270\emulator.py", line 723, in command_func
    cmd = self._exec_command(
        f'{name}({all_args})'.encode('utf8')
    )
  File "C:\projetos\pyx3270\pyx3270\emulator.py", line 793, in _exec_command
    cmd.execute()
    ~~~~~~~~~~~^^
  File "C:\projetos\pyx3270\pyx3270\emulator.py", line 182, in execute
    self.app.write(self.cmdstr + b'\n')
    ~~~~~~~~~~~~~~^^^^^^^^^^^^^^^^^^^^^
  File "C:\projetos\pyx3270\pyx3270\emulator.py", line 367, in write
    raise NotConnectedException
exceptions.NotConnectedException

During handling of the above exception, another exception occurred:

Traceback (most recent call last):
  File "C:\projetos\pyx3270\pyx3270\emulator.py", line 361, in write
    self.socket_fh.flush()
    ~~~~~~~~~~~~~~~~~~~~^^
  File "C:\Users\e5674469\.pyenv\pyenv-win\versions\3.13.1\Lib\socket.py", line 737, in write
    return self._sock.send(b)
           ~~~~~~~~~~~~~~~^^^
ConnectionResetError: [WinError 10054] An existing connection was forcibly closed by the remote host

During handling of the above exception, another exception occurred:

Traceback (most recent call last):
  File "C:\projetos\pyx3270\pyx3270\emulator.py", line 870, in reconnect_host
    self.terminate()
    ~~~~~~~~~~~~~~^^
  File "C:\projetos\pyx3270\pyx3270\emulator.py", line 806, in terminate
    self.quit()
    ~~~~~~~~~^^
  File "C:\projetos\pyx3270\pyx3270\emulator.py", line 723, in command_func
    cmd = self._exec_command(
        f'{name}({all_args})'.encode('utf8')
    )
  File "C:\projetos\pyx3270\pyx3270\emulator.py", line 793, in _exec_command
    cmd.execute()
    ~~~~~~~~~~~^^
  File "C:\projetos\pyx3270\pyx3270\emulator.py", line 182, in execute
    self.app.write(self.cmdstr + b'\n')
    ~~~~~~~~~~~~~~^^^^^^^^^^^^^^^^^^^^^
  File "C:\projetos\pyx3270\pyx3270\emulator.py", line 367, in write
    raise NotConnectedException
exceptions.NotConnectedException

During handling of the above exception, another exception occurred:

Traceback (most recent call last):
  File "C:\projetos\pyx3270\pyx3270\emulator.py", line 375, in readline
    line = self.socket_fh.readline()
  File "C:\Users\e5674469\.pyenv\pyenv-win\versions\3.13.1\Lib\socket.py", line 719, in readinto
    return self._sock.recv_into(b)
           ~~~~~~~~~~~~~~~~~~~~^^^
ConnectionResetError: [WinError 10054] An existing connection was forcibly closed by the remote host

During handling of the above exception, another exception occurred:

Traceback (most recent call last):
  File "C:\projetos\pyx3270\pyx3270\emulator.py", line 852, in connect_host
    self.wait(5, '3270mode')
    ~~~~~~~~~^^^^^^^^^^^^^^^
  File "C:\projetos\pyx3270\pyx3270\emulator.py", line 723, in command_func
    cmd = self._exec_command(
        f'{name}({all_args})'.encode('utf8')
    )
  File "C:\projetos\pyx3270\pyx3270\emulator.py", line 793, in _exec_command
    cmd.execute()
    ~~~~~~~~~~~^^
  File "C:\projetos\pyx3270\pyx3270\emulator.py", line 185, in execute
    line = self.app.readline()
  File "C:\projetos\pyx3270\pyx3270\emulator.py", line 380, in readline
    raise NotConnectedException
exceptions.NotConnectedException
